[2023-10-30T01:02:54.906+0000] {taskinstance.py:1159} INFO - Dependencies all met for dep_context=non-requeueable deps ti=<TaskInstance: asteroides-etl-dag.asteroides-etl-task scheduled__2023-09-30T00:00:00+00:00 [queued]>
[2023-10-30T01:02:54.934+0000] {taskinstance.py:1159} INFO - Dependencies all met for dep_context=requeueable deps ti=<TaskInstance: asteroides-etl-dag.asteroides-etl-task scheduled__2023-09-30T00:00:00+00:00 [queued]>
[2023-10-30T01:02:54.936+0000] {taskinstance.py:1361} INFO - Starting attempt 1 of 5
[2023-10-30T01:02:54.969+0000] {taskinstance.py:1382} INFO - Executing <Task(BashOperator): asteroides-etl-task> on 2023-09-30 00:00:00+00:00
[2023-10-30T01:02:54.980+0000] {standard_task_runner.py:57} INFO - Started process 1750 to run task
[2023-10-30T01:02:54.986+0000] {standard_task_runner.py:84} INFO - Running: ['***', 'tasks', 'run', 'asteroides-etl-dag', 'asteroides-etl-task', 'scheduled__2023-09-30T00:00:00+00:00', '--job-id', '125', '--raw', '--subdir', 'DAGS_FOLDER/asteroides-etl_dag.py', '--cfg-path', '/tmp/tmp3zqeb79x']
[2023-10-30T01:02:54.989+0000] {standard_task_runner.py:85} INFO - Job 125: Subtask asteroides-etl-task
[2023-10-30T01:02:55.114+0000] {task_command.py:416} INFO - Running <TaskInstance: asteroides-etl-dag.asteroides-etl-task scheduled__2023-09-30T00:00:00+00:00 [running]> on host ac9f9bef16c9
[2023-10-30T01:02:55.260+0000] {taskinstance.py:1662} INFO - Exporting env vars: AIRFLOW_CTX_DAG_OWNER='Norman Ruiz' AIRFLOW_CTX_DAG_ID='asteroides-etl-dag' AIRFLOW_CTX_TASK_ID='asteroides-etl-task' AIRFLOW_CTX_EXECUTION_DATE='2023-09-30T00:00:00+00:00' AIRFLOW_CTX_TRY_NUMBER='1' AIRFLOW_CTX_DAG_RUN_ID='scheduled__2023-09-30T00:00:00+00:00'
[2023-10-30T01:02:55.262+0000] {subprocess.py:63} INFO - Tmp dir root location: /tmp
[2023-10-30T01:02:55.264+0000] {subprocess.py:75} INFO - Running command: ['/bin/bash', '-c', 'echo ya casi lo tengo!!!!']
[2023-10-30T01:02:55.286+0000] {subprocess.py:86} INFO - Output:
[2023-10-30T01:02:55.289+0000] {subprocess.py:93} INFO - ya casi lo tengo!!!!
[2023-10-30T01:02:55.290+0000] {subprocess.py:97} INFO - Command exited with return code 0
[2023-10-30T01:02:55.327+0000] {taskinstance.py:1400} INFO - Marking task as SUCCESS. dag_id=asteroides-etl-dag, task_id=asteroides-etl-task, execution_date=20230930T000000, start_date=20231030T010254, end_date=20231030T010255
[2023-10-30T01:02:55.370+0000] {local_task_job_runner.py:228} INFO - Task exited with return code 0
[2023-10-30T01:02:55.397+0000] {taskinstance.py:2778} INFO - 0 downstream tasks scheduled from follow-on schedule check
[2023-10-30T16:00:31.554+0000] {taskinstance.py:1159} INFO - Dependencies all met for dep_context=non-requeueable deps ti=<TaskInstance: asteroides-etl-dag.asteroides-etl-task scheduled__2023-09-30T00:00:00+00:00 [queued]>
[2023-10-30T16:00:31.567+0000] {taskinstance.py:1159} INFO - Dependencies all met for dep_context=requeueable deps ti=<TaskInstance: asteroides-etl-dag.asteroides-etl-task scheduled__2023-09-30T00:00:00+00:00 [queued]>
[2023-10-30T16:00:31.568+0000] {taskinstance.py:1361} INFO - Starting attempt 1 of 5
[2023-10-30T16:00:31.586+0000] {taskinstance.py:1382} INFO - Executing <Task(DockerOperator): asteroides-etl-task> on 2023-09-30 00:00:00+00:00
[2023-10-30T16:00:31.593+0000] {standard_task_runner.py:57} INFO - Started process 4747 to run task
[2023-10-30T16:00:31.596+0000] {standard_task_runner.py:84} INFO - Running: ['***', 'tasks', 'run', 'asteroides-etl-dag', 'asteroides-etl-task', 'scheduled__2023-09-30T00:00:00+00:00', '--job-id', '578', '--raw', '--subdir', 'DAGS_FOLDER/asteroides-etl_dag.py', '--cfg-path', '/tmp/tmp86mwd2sb']
[2023-10-30T16:00:31.598+0000] {standard_task_runner.py:85} INFO - Job 578: Subtask asteroides-etl-task
[2023-10-30T16:00:31.650+0000] {task_command.py:416} INFO - Running <TaskInstance: asteroides-etl-dag.asteroides-etl-task scheduled__2023-09-30T00:00:00+00:00 [running]> on host d87e86d3d093
[2023-10-30T16:00:31.733+0000] {taskinstance.py:1662} INFO - Exporting env vars: AIRFLOW_CTX_DAG_OWNER='Norman Ruiz' AIRFLOW_CTX_DAG_ID='asteroides-etl-dag' AIRFLOW_CTX_TASK_ID='asteroides-etl-task' AIRFLOW_CTX_EXECUTION_DATE='2023-09-30T00:00:00+00:00' AIRFLOW_CTX_TRY_NUMBER='1' AIRFLOW_CTX_DAG_RUN_ID='scheduled__2023-09-30T00:00:00+00:00'
[2023-10-30T16:00:31.746+0000] {taskinstance.py:1937} ERROR - Task failed with exception
Traceback (most recent call last):
  File "/home/airflow/.local/lib/python3.8/site-packages/urllib3/connectionpool.py", line 714, in urlopen
    httplib_response = self._make_request(
  File "/home/airflow/.local/lib/python3.8/site-packages/urllib3/connectionpool.py", line 415, in _make_request
    conn.request(method, url, **httplib_request_kw)
  File "/home/airflow/.local/lib/python3.8/site-packages/urllib3/connection.py", line 244, in request
    super(HTTPConnection, self).request(method, url, body=body, headers=headers)
  File "/usr/local/lib/python3.8/http/client.py", line 1256, in request
    self._send_request(method, url, body, headers, encode_chunked)
  File "/usr/local/lib/python3.8/http/client.py", line 1302, in _send_request
    self.endheaders(body, encode_chunked=encode_chunked)
  File "/usr/local/lib/python3.8/http/client.py", line 1251, in endheaders
    self._send_output(message_body, encode_chunked=encode_chunked)
  File "/usr/local/lib/python3.8/http/client.py", line 1011, in _send_output
    self.send(msg)
  File "/usr/local/lib/python3.8/http/client.py", line 951, in send
    self.connect()
  File "/home/airflow/.local/lib/python3.8/site-packages/docker/transport/unixconn.py", line 27, in connect
    sock.connect(self.unix_socket)
FileNotFoundError: [Errno 2] No such file or directory

During handling of the above exception, another exception occurred:

Traceback (most recent call last):
  File "/home/airflow/.local/lib/python3.8/site-packages/requests/adapters.py", line 486, in send
    resp = conn.urlopen(
  File "/home/airflow/.local/lib/python3.8/site-packages/urllib3/connectionpool.py", line 798, in urlopen
    retries = retries.increment(
  File "/home/airflow/.local/lib/python3.8/site-packages/urllib3/util/retry.py", line 550, in increment
    raise six.reraise(type(error), error, _stacktrace)
  File "/home/airflow/.local/lib/python3.8/site-packages/urllib3/packages/six.py", line 769, in reraise
    raise value.with_traceback(tb)
  File "/home/airflow/.local/lib/python3.8/site-packages/urllib3/connectionpool.py", line 714, in urlopen
    httplib_response = self._make_request(
  File "/home/airflow/.local/lib/python3.8/site-packages/urllib3/connectionpool.py", line 415, in _make_request
    conn.request(method, url, **httplib_request_kw)
  File "/home/airflow/.local/lib/python3.8/site-packages/urllib3/connection.py", line 244, in request
    super(HTTPConnection, self).request(method, url, body=body, headers=headers)
  File "/usr/local/lib/python3.8/http/client.py", line 1256, in request
    self._send_request(method, url, body, headers, encode_chunked)
  File "/usr/local/lib/python3.8/http/client.py", line 1302, in _send_request
    self.endheaders(body, encode_chunked=encode_chunked)
  File "/usr/local/lib/python3.8/http/client.py", line 1251, in endheaders
    self._send_output(message_body, encode_chunked=encode_chunked)
  File "/usr/local/lib/python3.8/http/client.py", line 1011, in _send_output
    self.send(msg)
  File "/usr/local/lib/python3.8/http/client.py", line 951, in send
    self.connect()
  File "/home/airflow/.local/lib/python3.8/site-packages/docker/transport/unixconn.py", line 27, in connect
    sock.connect(self.unix_socket)
urllib3.exceptions.ProtocolError: ('Connection aborted.', FileNotFoundError(2, 'No such file or directory'))

During handling of the above exception, another exception occurred:

Traceback (most recent call last):
  File "/home/airflow/.local/lib/python3.8/site-packages/docker/api/client.py", line 214, in _retrieve_server_version
    return self.version(api_version=False)["ApiVersion"]
  File "/home/airflow/.local/lib/python3.8/site-packages/docker/api/daemon.py", line 181, in version
    return self._result(self._get(url), json=True)
  File "/home/airflow/.local/lib/python3.8/site-packages/docker/utils/decorators.py", line 46, in inner
    return f(self, *args, **kwargs)
  File "/home/airflow/.local/lib/python3.8/site-packages/docker/api/client.py", line 237, in _get
    return self.get(url, **self._set_request_timeout(kwargs))
  File "/home/airflow/.local/lib/python3.8/site-packages/requests/sessions.py", line 602, in get
    return self.request("GET", url, **kwargs)
  File "/home/airflow/.local/lib/python3.8/site-packages/requests/sessions.py", line 589, in request
    resp = self.send(prep, **send_kwargs)
  File "/home/airflow/.local/lib/python3.8/site-packages/requests/sessions.py", line 703, in send
    r = adapter.send(request, **kwargs)
  File "/home/airflow/.local/lib/python3.8/site-packages/requests/adapters.py", line 501, in send
    raise ConnectionError(err, request=request)
requests.exceptions.ConnectionError: ('Connection aborted.', FileNotFoundError(2, 'No such file or directory'))

During handling of the above exception, another exception occurred:

Traceback (most recent call last):
  File "/home/airflow/.local/lib/python3.8/site-packages/airflow/providers/docker/operators/docker.py", line 462, in execute
    if self.force_pull or not self.cli.images(name=self.image):
  File "/home/airflow/.local/lib/python3.8/site-packages/airflow/providers/docker/operators/docker.py", line 333, in cli
    return self.hook.api_client
  File "/usr/local/lib/python3.8/functools.py", line 967, in __get__
    val = self.func(instance)
  File "/home/airflow/.local/lib/python3.8/site-packages/airflow/providers/docker/hooks/docker.py", line 120, in api_client
    client = APIClient(
  File "/home/airflow/.local/lib/python3.8/site-packages/docker/api/client.py", line 197, in __init__
    self._version = self._retrieve_server_version()
  File "/home/airflow/.local/lib/python3.8/site-packages/docker/api/client.py", line 221, in _retrieve_server_version
    raise DockerException(
docker.errors.DockerException: Error while fetching server API version: ('Connection aborted.', FileNotFoundError(2, 'No such file or directory'))
[2023-10-30T16:00:31.768+0000] {taskinstance.py:1400} INFO - Marking task as UP_FOR_RETRY. dag_id=asteroides-etl-dag, task_id=asteroides-etl-task, execution_date=20230930T000000, start_date=20231030T160031, end_date=20231030T160031
[2023-10-30T16:00:31.794+0000] {standard_task_runner.py:104} ERROR - Failed to execute job 578 for task asteroides-etl-task (Error while fetching server API version: ('Connection aborted.', FileNotFoundError(2, 'No such file or directory')); 4747)
[2023-10-30T16:00:31.849+0000] {local_task_job_runner.py:228} INFO - Task exited with return code 1
[2023-10-30T16:00:31.888+0000] {taskinstance.py:2778} INFO - 0 downstream tasks scheduled from follow-on schedule check
[2023-10-30T19:26:55.631+0000] {taskinstance.py:1159} INFO - Dependencies all met for dep_context=non-requeueable deps ti=<TaskInstance: asteroides-etl-dag.asteroides-etl-task scheduled__2023-09-30T00:00:00+00:00 [queued]>
[2023-10-30T19:26:55.652+0000] {taskinstance.py:1159} INFO - Dependencies all met for dep_context=requeueable deps ti=<TaskInstance: asteroides-etl-dag.asteroides-etl-task scheduled__2023-09-30T00:00:00+00:00 [queued]>
[2023-10-30T19:26:55.652+0000] {taskinstance.py:1361} INFO - Starting attempt 1 of 5
[2023-10-30T19:26:55.770+0000] {taskinstance.py:1382} INFO - Executing <Task(BashOperator): asteroides-etl-task> on 2023-09-30 00:00:00+00:00
[2023-10-30T19:26:55.782+0000] {standard_task_runner.py:57} INFO - Started process 8833 to run task
[2023-10-30T19:26:55.787+0000] {standard_task_runner.py:84} INFO - Running: ['***', 'tasks', 'run', 'asteroides-etl-dag', 'asteroides-etl-task', 'scheduled__2023-09-30T00:00:00+00:00', '--job-id', '993', '--raw', '--subdir', 'DAGS_FOLDER/asteroides-etl_dag.py', '--cfg-path', '/tmp/tmpmqhkb4xf']
[2023-10-30T19:26:55.789+0000] {standard_task_runner.py:85} INFO - Job 993: Subtask asteroides-etl-task
[2023-10-30T19:26:55.864+0000] {task_command.py:416} INFO - Running <TaskInstance: asteroides-etl-dag.asteroides-etl-task scheduled__2023-09-30T00:00:00+00:00 [running]> on host d87e86d3d093
[2023-10-30T19:26:55.991+0000] {taskinstance.py:1662} INFO - Exporting env vars: AIRFLOW_CTX_DAG_OWNER='Norman Ruiz' AIRFLOW_CTX_DAG_ID='asteroides-etl-dag' AIRFLOW_CTX_TASK_ID='asteroides-etl-task' AIRFLOW_CTX_EXECUTION_DATE='2023-09-30T00:00:00+00:00' AIRFLOW_CTX_TRY_NUMBER='1' AIRFLOW_CTX_DAG_RUN_ID='scheduled__2023-09-30T00:00:00+00:00'
[2023-10-30T19:26:55.993+0000] {subprocess.py:63} INFO - Tmp dir root location: /tmp
[2023-10-30T19:26:55.995+0000] {subprocess.py:75} INFO - Running command: ['/bin/bash', '-c', 'echo "Corrio !!!!"']
[2023-10-30T19:26:56.012+0000] {subprocess.py:86} INFO - Output:
[2023-10-30T19:26:56.015+0000] {subprocess.py:93} INFO - Corrio !!!!
[2023-10-30T19:26:56.016+0000] {subprocess.py:97} INFO - Command exited with return code 0
[2023-10-30T19:26:56.054+0000] {taskinstance.py:1400} INFO - Marking task as SUCCESS. dag_id=asteroides-etl-dag, task_id=asteroides-etl-task, execution_date=20230930T000000, start_date=20231030T192655, end_date=20231030T192656
[2023-10-30T19:26:56.122+0000] {local_task_job_runner.py:228} INFO - Task exited with return code 0
[2023-10-30T19:26:56.150+0000] {taskinstance.py:2778} INFO - 0 downstream tasks scheduled from follow-on schedule check
