[2023-10-30T01:03:08.709+0000] {taskinstance.py:1159} INFO - Dependencies all met for dep_context=non-requeueable deps ti=<TaskInstance: asteroides-etl-dag.asteroides-etl-task scheduled__2023-10-23T00:00:00+00:00 [queued]>
[2023-10-30T01:03:08.724+0000] {taskinstance.py:1159} INFO - Dependencies all met for dep_context=requeueable deps ti=<TaskInstance: asteroides-etl-dag.asteroides-etl-task scheduled__2023-10-23T00:00:00+00:00 [queued]>
[2023-10-30T01:03:08.724+0000] {taskinstance.py:1361} INFO - Starting attempt 1 of 5
[2023-10-30T01:03:08.750+0000] {taskinstance.py:1382} INFO - Executing <Task(BashOperator): asteroides-etl-task> on 2023-10-23 00:00:00+00:00
[2023-10-30T01:03:08.762+0000] {standard_task_runner.py:57} INFO - Started process 1821 to run task
[2023-10-30T01:03:08.772+0000] {standard_task_runner.py:84} INFO - Running: ['***', 'tasks', 'run', 'asteroides-etl-dag', 'asteroides-etl-task', 'scheduled__2023-10-23T00:00:00+00:00', '--job-id', '148', '--raw', '--subdir', 'DAGS_FOLDER/asteroides-etl_dag.py', '--cfg-path', '/tmp/tmp4gx3u0b1']
[2023-10-30T01:03:08.775+0000] {standard_task_runner.py:85} INFO - Job 148: Subtask asteroides-etl-task
[2023-10-30T01:03:08.856+0000] {task_command.py:416} INFO - Running <TaskInstance: asteroides-etl-dag.asteroides-etl-task scheduled__2023-10-23T00:00:00+00:00 [running]> on host ac9f9bef16c9
[2023-10-30T01:03:09.055+0000] {taskinstance.py:1662} INFO - Exporting env vars: AIRFLOW_CTX_DAG_OWNER='Norman Ruiz' AIRFLOW_CTX_DAG_ID='asteroides-etl-dag' AIRFLOW_CTX_TASK_ID='asteroides-etl-task' AIRFLOW_CTX_EXECUTION_DATE='2023-10-23T00:00:00+00:00' AIRFLOW_CTX_TRY_NUMBER='1' AIRFLOW_CTX_DAG_RUN_ID='scheduled__2023-10-23T00:00:00+00:00'
[2023-10-30T01:03:09.058+0000] {subprocess.py:63} INFO - Tmp dir root location: /tmp
[2023-10-30T01:03:09.064+0000] {subprocess.py:75} INFO - Running command: ['/bin/bash', '-c', 'echo ya casi lo tengo!!!!']
[2023-10-30T01:03:09.088+0000] {subprocess.py:86} INFO - Output:
[2023-10-30T01:03:09.093+0000] {subprocess.py:93} INFO - ya casi lo tengo!!!!
[2023-10-30T01:03:09.096+0000] {subprocess.py:97} INFO - Command exited with return code 0
[2023-10-30T01:03:09.150+0000] {taskinstance.py:1400} INFO - Marking task as SUCCESS. dag_id=asteroides-etl-dag, task_id=asteroides-etl-task, execution_date=20231023T000000, start_date=20231030T010308, end_date=20231030T010309
[2023-10-30T01:03:09.268+0000] {local_task_job_runner.py:228} INFO - Task exited with return code 0
[2023-10-30T01:03:09.317+0000] {taskinstance.py:2778} INFO - 0 downstream tasks scheduled from follow-on schedule check
[2023-10-30T16:16:56.994+0000] {taskinstance.py:1159} INFO - Dependencies all met for dep_context=non-requeueable deps ti=<TaskInstance: asteroides-etl-dag.asteroides-etl-task scheduled__2023-10-23T00:00:00+00:00 [queued]>
[2023-10-30T16:16:57.010+0000] {taskinstance.py:1159} INFO - Dependencies all met for dep_context=requeueable deps ti=<TaskInstance: asteroides-etl-dag.asteroides-etl-task scheduled__2023-10-23T00:00:00+00:00 [queued]>
[2023-10-30T16:16:57.011+0000] {taskinstance.py:1361} INFO - Starting attempt 1 of 5
[2023-10-30T16:16:57.152+0000] {taskinstance.py:1382} INFO - Executing <Task(DockerOperator): asteroides-etl-task> on 2023-10-23 00:00:00+00:00
[2023-10-30T16:16:57.165+0000] {standard_task_runner.py:57} INFO - Started process 5293 to run task
[2023-10-30T16:16:57.170+0000] {standard_task_runner.py:84} INFO - Running: ['***', 'tasks', 'run', 'asteroides-etl-dag', 'asteroides-etl-task', 'scheduled__2023-10-23T00:00:00+00:00', '--job-id', '729', '--raw', '--subdir', 'DAGS_FOLDER/asteroides-etl_dag.py', '--cfg-path', '/tmp/tmp8jtmm96h']
[2023-10-30T16:16:57.172+0000] {standard_task_runner.py:85} INFO - Job 729: Subtask asteroides-etl-task
[2023-10-30T16:16:57.249+0000] {task_command.py:416} INFO - Running <TaskInstance: asteroides-etl-dag.asteroides-etl-task scheduled__2023-10-23T00:00:00+00:00 [running]> on host d87e86d3d093
[2023-10-30T16:16:57.390+0000] {taskinstance.py:1662} INFO - Exporting env vars: AIRFLOW_CTX_DAG_OWNER='Norman Ruiz' AIRFLOW_CTX_DAG_ID='asteroides-etl-dag' AIRFLOW_CTX_TASK_ID='asteroides-etl-task' AIRFLOW_CTX_EXECUTION_DATE='2023-10-23T00:00:00+00:00' AIRFLOW_CTX_TRY_NUMBER='1' AIRFLOW_CTX_DAG_RUN_ID='scheduled__2023-10-23T00:00:00+00:00'
[2023-10-30T16:16:57.405+0000] {taskinstance.py:1937} ERROR - Task failed with exception
Traceback (most recent call last):
  File "/home/airflow/.local/lib/python3.8/site-packages/urllib3/connectionpool.py", line 714, in urlopen
    httplib_response = self._make_request(
  File "/home/airflow/.local/lib/python3.8/site-packages/urllib3/connectionpool.py", line 415, in _make_request
    conn.request(method, url, **httplib_request_kw)
  File "/home/airflow/.local/lib/python3.8/site-packages/urllib3/connection.py", line 244, in request
    super(HTTPConnection, self).request(method, url, body=body, headers=headers)
  File "/usr/local/lib/python3.8/http/client.py", line 1256, in request
    self._send_request(method, url, body, headers, encode_chunked)
  File "/usr/local/lib/python3.8/http/client.py", line 1302, in _send_request
    self.endheaders(body, encode_chunked=encode_chunked)
  File "/usr/local/lib/python3.8/http/client.py", line 1251, in endheaders
    self._send_output(message_body, encode_chunked=encode_chunked)
  File "/usr/local/lib/python3.8/http/client.py", line 1011, in _send_output
    self.send(msg)
  File "/usr/local/lib/python3.8/http/client.py", line 951, in send
    self.connect()
  File "/home/airflow/.local/lib/python3.8/site-packages/docker/transport/unixconn.py", line 27, in connect
    sock.connect(self.unix_socket)
FileNotFoundError: [Errno 2] No such file or directory

During handling of the above exception, another exception occurred:

Traceback (most recent call last):
  File "/home/airflow/.local/lib/python3.8/site-packages/requests/adapters.py", line 486, in send
    resp = conn.urlopen(
  File "/home/airflow/.local/lib/python3.8/site-packages/urllib3/connectionpool.py", line 798, in urlopen
    retries = retries.increment(
  File "/home/airflow/.local/lib/python3.8/site-packages/urllib3/util/retry.py", line 550, in increment
    raise six.reraise(type(error), error, _stacktrace)
  File "/home/airflow/.local/lib/python3.8/site-packages/urllib3/packages/six.py", line 769, in reraise
    raise value.with_traceback(tb)
  File "/home/airflow/.local/lib/python3.8/site-packages/urllib3/connectionpool.py", line 714, in urlopen
    httplib_response = self._make_request(
  File "/home/airflow/.local/lib/python3.8/site-packages/urllib3/connectionpool.py", line 415, in _make_request
    conn.request(method, url, **httplib_request_kw)
  File "/home/airflow/.local/lib/python3.8/site-packages/urllib3/connection.py", line 244, in request
    super(HTTPConnection, self).request(method, url, body=body, headers=headers)
  File "/usr/local/lib/python3.8/http/client.py", line 1256, in request
    self._send_request(method, url, body, headers, encode_chunked)
  File "/usr/local/lib/python3.8/http/client.py", line 1302, in _send_request
    self.endheaders(body, encode_chunked=encode_chunked)
  File "/usr/local/lib/python3.8/http/client.py", line 1251, in endheaders
    self._send_output(message_body, encode_chunked=encode_chunked)
  File "/usr/local/lib/python3.8/http/client.py", line 1011, in _send_output
    self.send(msg)
  File "/usr/local/lib/python3.8/http/client.py", line 951, in send
    self.connect()
  File "/home/airflow/.local/lib/python3.8/site-packages/docker/transport/unixconn.py", line 27, in connect
    sock.connect(self.unix_socket)
urllib3.exceptions.ProtocolError: ('Connection aborted.', FileNotFoundError(2, 'No such file or directory'))

During handling of the above exception, another exception occurred:

Traceback (most recent call last):
  File "/home/airflow/.local/lib/python3.8/site-packages/docker/api/client.py", line 214, in _retrieve_server_version
    return self.version(api_version=False)["ApiVersion"]
  File "/home/airflow/.local/lib/python3.8/site-packages/docker/api/daemon.py", line 181, in version
    return self._result(self._get(url), json=True)
  File "/home/airflow/.local/lib/python3.8/site-packages/docker/utils/decorators.py", line 46, in inner
    return f(self, *args, **kwargs)
  File "/home/airflow/.local/lib/python3.8/site-packages/docker/api/client.py", line 237, in _get
    return self.get(url, **self._set_request_timeout(kwargs))
  File "/home/airflow/.local/lib/python3.8/site-packages/requests/sessions.py", line 602, in get
    return self.request("GET", url, **kwargs)
  File "/home/airflow/.local/lib/python3.8/site-packages/requests/sessions.py", line 589, in request
    resp = self.send(prep, **send_kwargs)
  File "/home/airflow/.local/lib/python3.8/site-packages/requests/sessions.py", line 703, in send
    r = adapter.send(request, **kwargs)
  File "/home/airflow/.local/lib/python3.8/site-packages/requests/adapters.py", line 501, in send
    raise ConnectionError(err, request=request)
requests.exceptions.ConnectionError: ('Connection aborted.', FileNotFoundError(2, 'No such file or directory'))

During handling of the above exception, another exception occurred:

Traceback (most recent call last):
  File "/home/airflow/.local/lib/python3.8/site-packages/airflow/providers/docker/operators/docker.py", line 462, in execute
    if self.force_pull or not self.cli.images(name=self.image):
  File "/home/airflow/.local/lib/python3.8/site-packages/airflow/providers/docker/operators/docker.py", line 333, in cli
    return self.hook.api_client
  File "/usr/local/lib/python3.8/functools.py", line 967, in __get__
    val = self.func(instance)
  File "/home/airflow/.local/lib/python3.8/site-packages/airflow/providers/docker/hooks/docker.py", line 120, in api_client
    client = APIClient(
  File "/home/airflow/.local/lib/python3.8/site-packages/docker/api/client.py", line 197, in __init__
    self._version = self._retrieve_server_version()
  File "/home/airflow/.local/lib/python3.8/site-packages/docker/api/client.py", line 221, in _retrieve_server_version
    raise DockerException(
docker.errors.DockerException: Error while fetching server API version: ('Connection aborted.', FileNotFoundError(2, 'No such file or directory'))
[2023-10-30T16:16:57.426+0000] {taskinstance.py:1400} INFO - Marking task as UP_FOR_RETRY. dag_id=asteroides-etl-dag, task_id=asteroides-etl-task, execution_date=20231023T000000, start_date=20231030T161656, end_date=20231030T161657
[2023-10-30T16:16:57.448+0000] {standard_task_runner.py:104} ERROR - Failed to execute job 729 for task asteroides-etl-task (Error while fetching server API version: ('Connection aborted.', FileNotFoundError(2, 'No such file or directory')); 5293)
[2023-10-30T16:16:57.467+0000] {local_task_job_runner.py:228} INFO - Task exited with return code 1
[2023-10-30T16:16:57.499+0000] {taskinstance.py:2778} INFO - 0 downstream tasks scheduled from follow-on schedule check
[2023-10-30T19:27:08.370+0000] {taskinstance.py:1159} INFO - Dependencies all met for dep_context=non-requeueable deps ti=<TaskInstance: asteroides-etl-dag.asteroides-etl-task scheduled__2023-10-23T00:00:00+00:00 [queued]>
[2023-10-30T19:27:08.387+0000] {taskinstance.py:1159} INFO - Dependencies all met for dep_context=requeueable deps ti=<TaskInstance: asteroides-etl-dag.asteroides-etl-task scheduled__2023-10-23T00:00:00+00:00 [queued]>
[2023-10-30T19:27:08.388+0000] {taskinstance.py:1361} INFO - Starting attempt 1 of 5
[2023-10-30T19:27:08.414+0000] {taskinstance.py:1382} INFO - Executing <Task(BashOperator): asteroides-etl-task> on 2023-10-23 00:00:00+00:00
[2023-10-30T19:27:08.423+0000] {standard_task_runner.py:57} INFO - Started process 8901 to run task
[2023-10-30T19:27:08.428+0000] {standard_task_runner.py:84} INFO - Running: ['***', 'tasks', 'run', 'asteroides-etl-dag', 'asteroides-etl-task', 'scheduled__2023-10-23T00:00:00+00:00', '--job-id', '1016', '--raw', '--subdir', 'DAGS_FOLDER/asteroides-etl_dag.py', '--cfg-path', '/tmp/tmpvxjrog7n']
[2023-10-30T19:27:08.434+0000] {standard_task_runner.py:85} INFO - Job 1016: Subtask asteroides-etl-task
[2023-10-30T19:27:08.503+0000] {task_command.py:416} INFO - Running <TaskInstance: asteroides-etl-dag.asteroides-etl-task scheduled__2023-10-23T00:00:00+00:00 [running]> on host d87e86d3d093
[2023-10-30T19:27:08.620+0000] {taskinstance.py:1662} INFO - Exporting env vars: AIRFLOW_CTX_DAG_OWNER='Norman Ruiz' AIRFLOW_CTX_DAG_ID='asteroides-etl-dag' AIRFLOW_CTX_TASK_ID='asteroides-etl-task' AIRFLOW_CTX_EXECUTION_DATE='2023-10-23T00:00:00+00:00' AIRFLOW_CTX_TRY_NUMBER='1' AIRFLOW_CTX_DAG_RUN_ID='scheduled__2023-10-23T00:00:00+00:00'
[2023-10-30T19:27:08.622+0000] {subprocess.py:63} INFO - Tmp dir root location: /tmp
[2023-10-30T19:27:08.624+0000] {subprocess.py:75} INFO - Running command: ['/bin/bash', '-c', 'echo "Corrio !!!!"']
[2023-10-30T19:27:08.642+0000] {subprocess.py:86} INFO - Output:
[2023-10-30T19:27:08.645+0000] {subprocess.py:93} INFO - Corrio !!!!
[2023-10-30T19:27:08.646+0000] {subprocess.py:97} INFO - Command exited with return code 0
[2023-10-30T19:27:08.682+0000] {taskinstance.py:1400} INFO - Marking task as SUCCESS. dag_id=asteroides-etl-dag, task_id=asteroides-etl-task, execution_date=20231023T000000, start_date=20231030T192708, end_date=20231030T192708
[2023-10-30T19:27:08.727+0000] {local_task_job_runner.py:228} INFO - Task exited with return code 0
[2023-10-30T19:27:08.748+0000] {taskinstance.py:2778} INFO - 0 downstream tasks scheduled from follow-on schedule check
