[2023-10-30T01:01:49.614+0000] {taskinstance.py:1159} INFO - Dependencies all met for dep_context=non-requeueable deps ti=<TaskInstance: asteroides-etl-dag.asteroides-etl-task scheduled__2023-06-03T00:00:00+00:00 [queued]>
[2023-10-30T01:01:49.635+0000] {taskinstance.py:1159} INFO - Dependencies all met for dep_context=requeueable deps ti=<TaskInstance: asteroides-etl-dag.asteroides-etl-task scheduled__2023-06-03T00:00:00+00:00 [queued]>
[2023-10-30T01:01:49.637+0000] {taskinstance.py:1361} INFO - Starting attempt 1 of 5
[2023-10-30T01:01:49.666+0000] {taskinstance.py:1382} INFO - Executing <Task(BashOperator): asteroides-etl-task> on 2023-06-03 00:00:00+00:00
[2023-10-30T01:01:49.676+0000] {standard_task_runner.py:57} INFO - Started process 1378 to run task
[2023-10-30T01:01:49.682+0000] {standard_task_runner.py:84} INFO - Running: ['***', 'tasks', 'run', 'asteroides-etl-dag', 'asteroides-etl-task', 'scheduled__2023-06-03T00:00:00+00:00', '--job-id', '6', '--raw', '--subdir', 'DAGS_FOLDER/asteroides-etl_dag.py', '--cfg-path', '/tmp/tmp5df2xts5']
[2023-10-30T01:01:49.686+0000] {standard_task_runner.py:85} INFO - Job 6: Subtask asteroides-etl-task
[2023-10-30T01:01:49.791+0000] {task_command.py:416} INFO - Running <TaskInstance: asteroides-etl-dag.asteroides-etl-task scheduled__2023-06-03T00:00:00+00:00 [running]> on host ac9f9bef16c9
[2023-10-30T01:01:49.982+0000] {taskinstance.py:1662} INFO - Exporting env vars: AIRFLOW_CTX_DAG_OWNER='Norman Ruiz' AIRFLOW_CTX_DAG_ID='asteroides-etl-dag' AIRFLOW_CTX_TASK_ID='asteroides-etl-task' AIRFLOW_CTX_EXECUTION_DATE='2023-06-03T00:00:00+00:00' AIRFLOW_CTX_TRY_NUMBER='1' AIRFLOW_CTX_DAG_RUN_ID='scheduled__2023-06-03T00:00:00+00:00'
[2023-10-30T01:01:49.985+0000] {subprocess.py:63} INFO - Tmp dir root location: /tmp
[2023-10-30T01:01:49.990+0000] {subprocess.py:75} INFO - Running command: ['/bin/bash', '-c', 'echo ya casi lo tengo!!!!']
[2023-10-30T01:01:50.017+0000] {subprocess.py:86} INFO - Output:
[2023-10-30T01:01:50.022+0000] {subprocess.py:93} INFO - ya casi lo tengo!!!!
[2023-10-30T01:01:50.023+0000] {subprocess.py:97} INFO - Command exited with return code 0
[2023-10-30T01:01:50.065+0000] {taskinstance.py:1400} INFO - Marking task as SUCCESS. dag_id=asteroides-etl-dag, task_id=asteroides-etl-task, execution_date=20230603T000000, start_date=20231030T010149, end_date=20231030T010150
[2023-10-30T01:01:50.150+0000] {local_task_job_runner.py:228} INFO - Task exited with return code 0
[2023-10-30T01:01:50.184+0000] {taskinstance.py:2778} INFO - 0 downstream tasks scheduled from follow-on schedule check
[2023-10-30T15:02:53.453+0000] {taskinstance.py:1159} INFO - Dependencies all met for dep_context=non-requeueable deps ti=<TaskInstance: asteroides-etl-dag.asteroides-etl-task scheduled__2023-06-03T00:00:00+00:00 [queued]>
[2023-10-30T15:02:53.475+0000] {taskinstance.py:1159} INFO - Dependencies all met for dep_context=requeueable deps ti=<TaskInstance: asteroides-etl-dag.asteroides-etl-task scheduled__2023-06-03T00:00:00+00:00 [queued]>
[2023-10-30T15:02:53.476+0000] {taskinstance.py:1361} INFO - Starting attempt 1 of 5
[2023-10-30T15:02:53.507+0000] {taskinstance.py:1382} INFO - Executing <Task(BashOperator): asteroides-etl-task> on 2023-06-03 00:00:00+00:00
[2023-10-30T15:02:53.524+0000] {standard_task_runner.py:57} INFO - Started process 97 to run task
[2023-10-30T15:02:53.533+0000] {standard_task_runner.py:84} INFO - Running: ['***', 'tasks', 'run', 'asteroides-etl-dag', 'asteroides-etl-task', 'scheduled__2023-06-03T00:00:00+00:00', '--job-id', '4', '--raw', '--subdir', 'DAGS_FOLDER/asteroides-etl_dag.py', '--cfg-path', '/tmp/tmp9opj8ax6']
[2023-10-30T15:02:53.536+0000] {standard_task_runner.py:85} INFO - Job 4: Subtask asteroides-etl-task
[2023-10-30T15:02:53.658+0000] {task_command.py:416} INFO - Running <TaskInstance: asteroides-etl-dag.asteroides-etl-task scheduled__2023-06-03T00:00:00+00:00 [running]> on host d87e86d3d093
[2023-10-30T15:02:53.836+0000] {taskinstance.py:1662} INFO - Exporting env vars: AIRFLOW_CTX_DAG_OWNER='Norman Ruiz' AIRFLOW_CTX_DAG_ID='asteroides-etl-dag' AIRFLOW_CTX_TASK_ID='asteroides-etl-task' AIRFLOW_CTX_EXECUTION_DATE='2023-06-03T00:00:00+00:00' AIRFLOW_CTX_TRY_NUMBER='1' AIRFLOW_CTX_DAG_RUN_ID='scheduled__2023-06-03T00:00:00+00:00'
[2023-10-30T15:02:53.842+0000] {subprocess.py:63} INFO - Tmp dir root location: /tmp
[2023-10-30T15:02:53.845+0000] {subprocess.py:75} INFO - Running command: ['/bin/bash', '-c', 'docker run -it --name asteroides-etl asteroides-etl']
[2023-10-30T15:02:53.892+0000] {subprocess.py:86} INFO - Output:
[2023-10-30T15:02:53.981+0000] {subprocess.py:93} INFO - the input device is not a TTY
[2023-10-30T15:02:53.985+0000] {subprocess.py:97} INFO - Command exited with return code 1
[2023-10-30T15:02:54.015+0000] {taskinstance.py:1937} ERROR - Task failed with exception
Traceback (most recent call last):
  File "/home/airflow/.local/lib/python3.8/site-packages/airflow/operators/bash.py", line 210, in execute
    raise AirflowException(
airflow.exceptions.AirflowException: Bash command failed. The command returned a non-zero exit code 1.
[2023-10-30T15:02:54.025+0000] {taskinstance.py:1400} INFO - Marking task as UP_FOR_RETRY. dag_id=asteroides-etl-dag, task_id=asteroides-etl-task, execution_date=20230603T000000, start_date=20231030T150253, end_date=20231030T150254
[2023-10-30T15:02:54.064+0000] {standard_task_runner.py:104} ERROR - Failed to execute job 4 for task asteroides-etl-task (Bash command failed. The command returned a non-zero exit code 1.; 97)
[2023-10-30T15:02:54.117+0000] {local_task_job_runner.py:228} INFO - Task exited with return code 1
[2023-10-30T15:02:54.169+0000] {taskinstance.py:2778} INFO - 0 downstream tasks scheduled from follow-on schedule check
[2023-10-30T19:23:09.494+0000] {taskinstance.py:1159} INFO - Dependencies all met for dep_context=non-requeueable deps ti=<TaskInstance: asteroides-etl-dag.asteroides-etl-task scheduled__2023-06-03T00:00:00+00:00 [queued]>
[2023-10-30T19:23:09.514+0000] {taskinstance.py:1159} INFO - Dependencies all met for dep_context=requeueable deps ti=<TaskInstance: asteroides-etl-dag.asteroides-etl-task scheduled__2023-06-03T00:00:00+00:00 [queued]>
[2023-10-30T19:23:09.515+0000] {taskinstance.py:1361} INFO - Starting attempt 1 of 5
[2023-10-30T19:23:09.547+0000] {taskinstance.py:1382} INFO - Executing <Task(DockerOperator): asteroides-etl-task> on 2023-06-03 00:00:00+00:00
[2023-10-30T19:23:09.560+0000] {standard_task_runner.py:57} INFO - Started process 8238 to run task
[2023-10-30T19:23:09.564+0000] {standard_task_runner.py:84} INFO - Running: ['***', 'tasks', 'run', 'asteroides-etl-dag', 'asteroides-etl-task', 'scheduled__2023-06-03T00:00:00+00:00', '--job-id', '808', '--raw', '--subdir', 'DAGS_FOLDER/asteroides-etl_dag.py', '--cfg-path', '/tmp/tmpmy8sn4fx']
[2023-10-30T19:23:09.566+0000] {standard_task_runner.py:85} INFO - Job 808: Subtask asteroides-etl-task
[2023-10-30T19:23:09.653+0000] {task_command.py:416} INFO - Running <TaskInstance: asteroides-etl-dag.asteroides-etl-task scheduled__2023-06-03T00:00:00+00:00 [running]> on host d87e86d3d093
[2023-10-30T19:23:09.827+0000] {taskinstance.py:1662} INFO - Exporting env vars: AIRFLOW_CTX_DAG_OWNER='Norman Ruiz' AIRFLOW_CTX_DAG_ID='asteroides-etl-dag' AIRFLOW_CTX_TASK_ID='asteroides-etl-task' AIRFLOW_CTX_EXECUTION_DATE='2023-06-03T00:00:00+00:00' AIRFLOW_CTX_TRY_NUMBER='1' AIRFLOW_CTX_DAG_RUN_ID='scheduled__2023-06-03T00:00:00+00:00'
[2023-10-30T19:23:09.841+0000] {taskinstance.py:1937} ERROR - Task failed with exception
Traceback (most recent call last):
  File "/home/airflow/.local/lib/python3.8/site-packages/urllib3/connectionpool.py", line 714, in urlopen
    httplib_response = self._make_request(
  File "/home/airflow/.local/lib/python3.8/site-packages/urllib3/connectionpool.py", line 415, in _make_request
    conn.request(method, url, **httplib_request_kw)
  File "/home/airflow/.local/lib/python3.8/site-packages/urllib3/connection.py", line 244, in request
    super(HTTPConnection, self).request(method, url, body=body, headers=headers)
  File "/usr/local/lib/python3.8/http/client.py", line 1256, in request
    self._send_request(method, url, body, headers, encode_chunked)
  File "/usr/local/lib/python3.8/http/client.py", line 1302, in _send_request
    self.endheaders(body, encode_chunked=encode_chunked)
  File "/usr/local/lib/python3.8/http/client.py", line 1251, in endheaders
    self._send_output(message_body, encode_chunked=encode_chunked)
  File "/usr/local/lib/python3.8/http/client.py", line 1011, in _send_output
    self.send(msg)
  File "/usr/local/lib/python3.8/http/client.py", line 951, in send
    self.connect()
  File "/home/airflow/.local/lib/python3.8/site-packages/docker/transport/unixconn.py", line 27, in connect
    sock.connect(self.unix_socket)
FileNotFoundError: [Errno 2] No such file or directory

During handling of the above exception, another exception occurred:

Traceback (most recent call last):
  File "/home/airflow/.local/lib/python3.8/site-packages/requests/adapters.py", line 486, in send
    resp = conn.urlopen(
  File "/home/airflow/.local/lib/python3.8/site-packages/urllib3/connectionpool.py", line 798, in urlopen
    retries = retries.increment(
  File "/home/airflow/.local/lib/python3.8/site-packages/urllib3/util/retry.py", line 550, in increment
    raise six.reraise(type(error), error, _stacktrace)
  File "/home/airflow/.local/lib/python3.8/site-packages/urllib3/packages/six.py", line 769, in reraise
    raise value.with_traceback(tb)
  File "/home/airflow/.local/lib/python3.8/site-packages/urllib3/connectionpool.py", line 714, in urlopen
    httplib_response = self._make_request(
  File "/home/airflow/.local/lib/python3.8/site-packages/urllib3/connectionpool.py", line 415, in _make_request
    conn.request(method, url, **httplib_request_kw)
  File "/home/airflow/.local/lib/python3.8/site-packages/urllib3/connection.py", line 244, in request
    super(HTTPConnection, self).request(method, url, body=body, headers=headers)
  File "/usr/local/lib/python3.8/http/client.py", line 1256, in request
    self._send_request(method, url, body, headers, encode_chunked)
  File "/usr/local/lib/python3.8/http/client.py", line 1302, in _send_request
    self.endheaders(body, encode_chunked=encode_chunked)
  File "/usr/local/lib/python3.8/http/client.py", line 1251, in endheaders
    self._send_output(message_body, encode_chunked=encode_chunked)
  File "/usr/local/lib/python3.8/http/client.py", line 1011, in _send_output
    self.send(msg)
  File "/usr/local/lib/python3.8/http/client.py", line 951, in send
    self.connect()
  File "/home/airflow/.local/lib/python3.8/site-packages/docker/transport/unixconn.py", line 27, in connect
    sock.connect(self.unix_socket)
urllib3.exceptions.ProtocolError: ('Connection aborted.', FileNotFoundError(2, 'No such file or directory'))

During handling of the above exception, another exception occurred:

Traceback (most recent call last):
  File "/home/airflow/.local/lib/python3.8/site-packages/docker/api/client.py", line 214, in _retrieve_server_version
    return self.version(api_version=False)["ApiVersion"]
  File "/home/airflow/.local/lib/python3.8/site-packages/docker/api/daemon.py", line 181, in version
    return self._result(self._get(url), json=True)
  File "/home/airflow/.local/lib/python3.8/site-packages/docker/utils/decorators.py", line 46, in inner
    return f(self, *args, **kwargs)
  File "/home/airflow/.local/lib/python3.8/site-packages/docker/api/client.py", line 237, in _get
    return self.get(url, **self._set_request_timeout(kwargs))
  File "/home/airflow/.local/lib/python3.8/site-packages/requests/sessions.py", line 602, in get
    return self.request("GET", url, **kwargs)
  File "/home/airflow/.local/lib/python3.8/site-packages/requests/sessions.py", line 589, in request
    resp = self.send(prep, **send_kwargs)
  File "/home/airflow/.local/lib/python3.8/site-packages/requests/sessions.py", line 703, in send
    r = adapter.send(request, **kwargs)
  File "/home/airflow/.local/lib/python3.8/site-packages/requests/adapters.py", line 501, in send
    raise ConnectionError(err, request=request)
requests.exceptions.ConnectionError: ('Connection aborted.', FileNotFoundError(2, 'No such file or directory'))

During handling of the above exception, another exception occurred:

Traceback (most recent call last):
  File "/home/airflow/.local/lib/python3.8/site-packages/airflow/providers/docker/operators/docker.py", line 462, in execute
    if self.force_pull or not self.cli.images(name=self.image):
  File "/home/airflow/.local/lib/python3.8/site-packages/airflow/providers/docker/operators/docker.py", line 333, in cli
    return self.hook.api_client
  File "/usr/local/lib/python3.8/functools.py", line 967, in __get__
    val = self.func(instance)
  File "/home/airflow/.local/lib/python3.8/site-packages/airflow/providers/docker/hooks/docker.py", line 120, in api_client
    client = APIClient(
  File "/home/airflow/.local/lib/python3.8/site-packages/docker/api/client.py", line 197, in __init__
    self._version = self._retrieve_server_version()
  File "/home/airflow/.local/lib/python3.8/site-packages/docker/api/client.py", line 221, in _retrieve_server_version
    raise DockerException(
docker.errors.DockerException: Error while fetching server API version: ('Connection aborted.', FileNotFoundError(2, 'No such file or directory'))
[2023-10-30T19:23:09.863+0000] {taskinstance.py:1400} INFO - Marking task as UP_FOR_RETRY. dag_id=asteroides-etl-dag, task_id=asteroides-etl-task, execution_date=20230603T000000, start_date=20231030T192309, end_date=20231030T192309
[2023-10-30T19:23:09.886+0000] {standard_task_runner.py:104} ERROR - Failed to execute job 808 for task asteroides-etl-task (Error while fetching server API version: ('Connection aborted.', FileNotFoundError(2, 'No such file or directory')); 8238)
[2023-10-30T19:23:09.914+0000] {local_task_job_runner.py:228} INFO - Task exited with return code 1
[2023-10-30T19:23:09.948+0000] {taskinstance.py:2778} INFO - 0 downstream tasks scheduled from follow-on schedule check
[2023-10-30T19:25:47.697+0000] {taskinstance.py:1159} INFO - Dependencies all met for dep_context=non-requeueable deps ti=<TaskInstance: asteroides-etl-dag.asteroides-etl-task scheduled__2023-06-03T00:00:00+00:00 [queued]>
[2023-10-30T19:25:47.716+0000] {taskinstance.py:1159} INFO - Dependencies all met for dep_context=requeueable deps ti=<TaskInstance: asteroides-etl-dag.asteroides-etl-task scheduled__2023-06-03T00:00:00+00:00 [queued]>
[2023-10-30T19:25:47.718+0000] {taskinstance.py:1361} INFO - Starting attempt 1 of 5
[2023-10-30T19:25:47.750+0000] {taskinstance.py:1382} INFO - Executing <Task(BashOperator): asteroides-etl-task> on 2023-06-03 00:00:00+00:00
[2023-10-30T19:25:47.761+0000] {standard_task_runner.py:57} INFO - Started process 8461 to run task
[2023-10-30T19:25:47.766+0000] {standard_task_runner.py:84} INFO - Running: ['***', 'tasks', 'run', 'asteroides-etl-dag', 'asteroides-etl-task', 'scheduled__2023-06-03T00:00:00+00:00', '--job-id', '874', '--raw', '--subdir', 'DAGS_FOLDER/asteroides-etl_dag.py', '--cfg-path', '/tmp/tmpm9jkqv2a']
[2023-10-30T19:25:47.768+0000] {standard_task_runner.py:85} INFO - Job 874: Subtask asteroides-etl-task
[2023-10-30T19:25:47.860+0000] {task_command.py:416} INFO - Running <TaskInstance: asteroides-etl-dag.asteroides-etl-task scheduled__2023-06-03T00:00:00+00:00 [running]> on host d87e86d3d093
[2023-10-30T19:25:48.013+0000] {taskinstance.py:1662} INFO - Exporting env vars: AIRFLOW_CTX_DAG_OWNER='Norman Ruiz' AIRFLOW_CTX_DAG_ID='asteroides-etl-dag' AIRFLOW_CTX_TASK_ID='asteroides-etl-task' AIRFLOW_CTX_EXECUTION_DATE='2023-06-03T00:00:00+00:00' AIRFLOW_CTX_TRY_NUMBER='1' AIRFLOW_CTX_DAG_RUN_ID='scheduled__2023-06-03T00:00:00+00:00'
[2023-10-30T19:25:48.015+0000] {subprocess.py:63} INFO - Tmp dir root location: /tmp
[2023-10-30T19:25:48.017+0000] {subprocess.py:75} INFO - Running command: ['/bin/bash', '-c', 'echo "Corrio !!!!"']
[2023-10-30T19:25:48.043+0000] {subprocess.py:86} INFO - Output:
[2023-10-30T19:25:48.048+0000] {subprocess.py:93} INFO - Corrio !!!!
[2023-10-30T19:25:48.050+0000] {subprocess.py:97} INFO - Command exited with return code 0
[2023-10-30T19:25:48.100+0000] {taskinstance.py:1400} INFO - Marking task as SUCCESS. dag_id=asteroides-etl-dag, task_id=asteroides-etl-task, execution_date=20230603T000000, start_date=20231030T192547, end_date=20231030T192548
[2023-10-30T19:25:48.222+0000] {local_task_job_runner.py:228} INFO - Task exited with return code 0
[2023-10-30T19:25:48.248+0000] {taskinstance.py:2778} INFO - 0 downstream tasks scheduled from follow-on schedule check
